Workbook

Sheet Instructions
B2: Emory Lab Atlas: wet/dry labelling check
B3: 150 investigators, one row each on the Label sheet. Allow about 2 minutes a person.
B5: Why | C5: The atlas places every investigator on a wet/dry axis with a model. Its accuracy was measured against labels that Claude assigned by reading each record. This sheet checks those labels: you label the same people yourself, without seeing Claude’s label or the model’s, and the two are compared.
B7: Keep it blind | C7: Do not open the atlas, the repository or anyone else’s copy of this sheet while you label. If two of you are labelling, work separately and do not compare notes until both are done.
B9: What to do | C9: 1. Go to the Label sheet. For each row, click "Read record" to see the person’s full record (publication titles, profile text, grants, units, degrees), then click "Back to label". 2. In the yellow Label cell pick W, D, H or U from the list (definitions below). 3. In the yellow Sure? cell pick 1 if you are sure, 2 if it is a judgment call. 4. Optionally, a short note: the reason, especially for H, U or anything surprising. 5. Optional, and only after step 2: if you know the lab or look at its website and would label it differently from what the record alone suggests, put that label in "After web check". Edit only the yellow cells. Row 5 on the Label sheet is a worked example and is not scored.
B11: W wet | C11: Most of the output rests on bench or laboratory experiments that the group itself runs: cells, molecules, proteins, nucleic acids, microbes, tissues and specimens processed in a lab; animal models (mouse, rat, non-human primate, zebrafish, fly, worm); chemistry and synthesis; structural biology; biomaterials and devices built and tested at the bench; electrophysiology in tissue or animals; experimental imaging of specimens or animals.
B13: D dry | C13: Most of the output is research without a bench: computational biology, bioinformatics, statistics; epidemiology and population health; clinical research on patients, records, registries or trials; case reports; surveys, interviews, qualitative and behavioural research; health services, policy, economics and education; image interpretation. Clinical research counts as dry: the axis is bench versus no bench, not laboratory versus computer.
B15: H hybrid | C15: Both modes are a substantial, deliberate part of the output (roughly a quarter or more each), or the group pairs bench experiments with computational or clinical-cohort analysis as its method (mouse models alongside patient cohorts; sequencing experiments alongside the bioinformatics built to read them).
B17: U can’t tell | C17: Too little to judge: no profile and only a couple of uninformative titles, or only editorials, commentaries and guidelines.
B19: Reading rules | C19: • Judge the person, not the department. A pathologist can run a bench lab or only read slides. • Weigh the bulk of the titles, not the most striking one. One mouse paper among forty clinical papers is still dry. • Multi-centre trials and consortium papers count as what they are (a clinician’s trial papers are dry). • Set aside titles plainly written by a namesake (a different field or era). • Clinic addresses, board certifications and languages spoken say someone is a clinician; they do not by themselves say whether they also run a bench.
B21: When done | C21: Save the file with your initials in the name (for example labelling_sheet_JS.xlsx) and send it back. The Progress sheet shows how many rows are left.

Sheet Label
A1: Label each person W, D, H or U. Edit only the yellow cells.
A2: W wet (bench) D dry (no bench; clinical counts as dry) H hybrid (both, a quarter or more each) U can’t tell. Sure?: 1 sure, 2 judgment call. Full definitions on the Instructions sheet.
A4: Code | B4: Name | C4: Units | D4: Degrees | E4: Titles | F4: Record | G4: Label | H4: Sure? | I4: Note | J4: After web check
A5: EX | B5: (example) A. Researcher | C5: Pharmacology & Chemical Biology (SOM) | D5: PhD | E5: 34 | F5: (example) | G5: W | H5: 1 | I5: Most titles are mouse and cell-line experiments
A6: H001 | B6: Beau Bruce | C6: Ophthalmology (SOM) Cancer Prevention & Control (Winship) | D6: MD; PhD; MS; BS | E6: 25 | F6: =HYPERLINK("#Records!A1","Read record →") -> Read record →
A7: H002 | B7: Kelly Bijanki | C7: Neurosurgery (SOM) | D7: PhD; BA | E7: 10 | F7: =HYPERLINK("#Records!A35","Read record →") -> Read record →
A8: H003 | B8: Deborah Andresen | C8: Pediatrics (SOM) | D8: MD | E8: 3 | F8: =HYPERLINK("#Records!A53","Read record →") -> Read record →
A9: H004 | B9: John Sweeney | C9: Surgery (SOM) | D9: MD | E9: 0 | F9: =HYPERLINK("#Records!A64","Read record →") -> Read record →
A10: H005 | B10: Lucas Felipe Bastos Horta | C10: Office of Medical Education & Student Affairs (SOM) | D10: MD | E10: 2 | F10: =HYPERLINK("#Records!A74","Read record →") -> Read record →
A11: H006 | B11: Bryce Rushing | C11: Medicine (SOM) | D11: MD | E11: 1 | F11: =HYPERLINK("#Records!A85","Read record →") -> Read record →
A12: H007 | B12: Paul Ghareeb | C12: Surgery (SOM) | D12: MD | E12: 34 | F12: =HYPERLINK("#Records!A94","Read record →") -> Read record →
A13: H008 | B13: Joshua Vova | C13: Pediatrics (SOM) REACH Center (CHOA) PTC (CHOA) | D13: MD | E13: 6 | F13: =HYPERLINK("#Records!A137","Read record →") -> Read record →
A14: H009 | B14: Reneeta Basu | C14: Family & Preventive Med. (SOM) | D14: DO | E14: 0 | F14: =HYPERLINK("#Records!A152","Read record →") -> Read record →
A15: H010 | B15: Stephanie Davis | C15: Psychiatry (SOM) | D15: PsyD; MS | E15: 20 | F15: =HYPERLINK("#Records!A162","Read record →") -> Read record →
A16: H011 | B16: Cheryl Maier | C16: Pathology & Lab Medicine (SOM) | D16: MD; PhD | E16: 71 | F16: =HYPERLINK("#Records!A190","Read record →") -> Read record →
A17: H012 | B17: Amanda Romeu | C17: Pediatrics (SOM) | D17: DO | E17: 1 | F17: =HYPERLINK("#Records!A260","Read record →") -> Read record →
A18: H013 | B18: Joshy Jacob | C18: Microbiology & Immunology (SOM) Emory Vaccine Center (Vaccine) Emory Center for AIDS Research (Vaccine) … | D18: PhD; BS | E18: 28 | F18: =HYPERLINK("#Records!A269","Read record →") -> Read record →
A19: H014 | B19: Kim Hoang | C19: Medicine (SOM) | D19: PhD | E19: 21 | F19: =HYPERLINK("#Records!A306","Read record →") -> Read record →
A20: H015 | B20: Elizabeth Draganova | C20: Biochemistry (SOM) | E20: 11 | F20: =HYPERLINK("#Records!A335","Read record →") -> Read record →
A21: H016 | B21: Michelle Kegler | C21: Cancer Prevention & Control (Winship) Behavioral, Social, & Health Education Scien… (RSPH) Environmental Health (RSPH) … | D21: BA; MD; MPH; PhD | E21: 73 | F21: =HYPERLINK("#Records!A355","Read record →") -> Read record →
A22: H017 | B22: John Blevins | C22: Environmental Health (RSPH) Global Health (RSPH) | D22: PhD; MPH | E22: 34 | F22: =HYPERLINK("#Records!A425","Read record →") -> Read record →
A23: H018 | B23: Hassan Monfared | C23: Rehabilitation Medicine (SOM) | D23: MD | E23: 0 | F23: =HYPERLINK("#Records!A468","Read record →") -> Read record →
A24: H019 | B24: Phillip Zhe Sun | C24: Discovery & Developmental Therapeutics (Winship) Neuropharmacology (EPC) | D24: PhD | E24: 122 | F24: =HYPERLINK("#Records!A478","Read record →") -> Read record →
A25: H020 | B25: Joseph Bishop | C25: Psychiatry (SOM) | D25: MD | E25: 1 | F25: =HYPERLINK("#Records!A548","Read record →") -> Read record →
A26: H021 | B26: Nicole Carlson | C26: General faculty (Nursing) | D26: PhD, CNM, FACNM, FAAN | E26: 64 | F26: =HYPERLINK("#Records!A557","Read record →") -> Read record →
A27: H022 | B27: Lindsay Kibuyaga | C27: Pediatrics (SOM) | D27: MD; MPH; BA | E27: 0 | F27: =HYPERLINK("#Records!A627","Read record →") -> Read record →
A28: H023 | B28: Teresa B. Ades | C28: General faculty (Nursing) | D28: DNP, FNP-BC, AOCN | E28: 3 | F28: =HYPERLINK("#Records!A637","Read record →") -> Read record →
A29: H024 | B29: Michelle Sheng | C29: Urology (SOM) | D29: MD | E29: 2 | F29: =HYPERLINK("#Records!A648","Read record →") -> Read record →
A30: H025 | B30: Yih-Ling Tzeng | C30: Medicine (SOM) | D30: PhD; BS | E30: 60 | F30: =HYPERLINK("#Records!A659","Read record →") -> Read record →
A31: H026 | B31: Jidong Guo | C31: Psychiatry (SOM) | E31: 18 | F31: =HYPERLINK("#Records!A728","Read record →") -> Read record →
A32: H027 | B32: Cinnamon Sullivan | C32: Anesthesiology (SOM) | D32: MD; BA | E32: 7 | F32: =HYPERLINK("#Records!A754","Read record →") -> Read record →
A33: H028 | B33: James Thornton | C33: Anesthesiology (SOM) | D33: MMSc; CAA | E33: 1 | F33: =HYPERLINK("#Records!A770","Read record →") -> Read record →
A34: H029 | B34: Abayomi Oyenuga | C34: Medicine (SOM) | E34: 2 | F34: =HYPERLINK("#Records!A779","Read record →") -> Read record →
A35: H030 | B35: Shruti Bhatt | C35: Discovery & Developmental Therapeutics (Winship) | D35: PhD | E35: 34 | F35: =HYPERLINK("#Records!A789","Read record →") -> Read record →
A36: H031 | B36: Andrew Furman | C36: Psychiatry (SOM) | D36: MD; BA | E36: 6 | F36: =HYPERLINK("#Records!A831","Read record →") -> Read record →
A37: H032 | B37: Sonya Green | C37: Family & Preventive Med. (SOM) | D37: PA-C | E37: 2 | F37: =HYPERLINK("#Records!A846","Read record →") -> Read record →
A38: H033 | B38: Thomas Dodson | C38: Surgery (SOM) | D38: MD; BA | E38: 19 | F38: =HYPERLINK("#Records!A857","Read record →") -> Read record →
A39: H034 | B39: Kindell Schoffner | C39: Pediatrics (SOM) | D39: PsyD | E39: 2 | F39: =HYPERLINK("#Records!A885","Read record →") -> Read record →
A40: H035 | B40: Sarah Koumtouzoua | C40: Medicine (SOM) | D40: MD; BS | E40: 3 | F40: =HYPERLINK("#Records!A896","Read record →") -> Read record →
A41: H036 | B41: Enoch Leung | C41: Rehabilitation Medicine (SOM) | D41: MD; PhD | E41: 1 | F41: =HYPERLINK("#Records!A907","Read record →") -> Read record →
...

Sheet Records
A1: H001 | B1: Beau Bruce · MD; PhD; MS; BS
B2: =HYPERLINK("#Label!G6","← Back to label (row 6)") -> ← Back to label (row 6)
A3: Units | B3: Ophthalmology (SOM) Cancer Prevention & Control (Winship)
A4: Email | B4: bbbruce@emory.edu
A5: Profile page | B5: https://winshipcancer.emory.edu/profiles/bruce-beau.php
A6: Profile text | B6: Beau B. Bruce, MD, PhD, is an assistant professor in the Department of Ophthalmology at Emory University School of Medicine and Assistant Professor of Epidemiology at Rollins School of Public Health. Dr. Bruce is currently an analytics specialist in the Enteric Diseases Epidemiology Branch at Centers for Disease Control and Prevention. Dr. Bruce received his medical degree from Emory University School of Medicine and his PhD in Epidemiology from Rollins School of Public Health at Emory University. Assistant Professor, Department of Ophthalmology Rollins School of Public Health, Emory University
A7: Grant titles | B7: (none on the record)
A8: Titles (25) | B8: 2026 Enhanced Bayesian Spline Regression Approach for Modelling Trends in Infections Caused by Pathogens Commonly Transmitted Through Food.
B9: 2026 A Case-Case Study of Sporadic and Outbreak-Associated Listeriosis Exposures: Listeria Initiative Food History Data, 2016-2022.
B10: 2025 Nonarteritic Anterior Ischemic Optic Neuropathy in Black Patients
B11: 2025 Factors Associated with Medical Care-Seeking and Stool Sample Submission for Diarrheal Illness, FoodNet, United States, 2018-2019
B12: 2025 Emergency Department Nonmydriatic Fundus Photography Expedites Care for Patients Referred for Papilledema
B13: 2025 GLP-1 RAs for Idiopathic Intracranial Hypertension-Time for a Trial
B14: 2025 Factors associated with vision loss in idiopathic intracranial hypertension patients with severe papilledema.
B15: 2024 An Approach to Describe Salmonella Serotypes of Concern for Outbreaks: Using Burden and Trajectory of Outbreak-related Illnesses Associated with Meat and Poultry.
B16: 2024 Machine learning to attribute the source of Campylobacter infections in the United States: A retrospective analysis of national surveillance data.
B17: 2024 Application of a Deep Learning System to Detect Papilledema on Nonmydriatic Ocular Fundus Photographs in an Emergency Department.
B18: 2024 Clinical Outcomes of Patients With Nontyphoidal Salmonella Infections by Isolate Resistance-Foodborne Diseases Active Surveillance Network, 10 US Sites, 2004-2018.
B19: 2024 Syndromic Gastrointestinal Panel Diagnostic Tests Have Changed our Understanding of the Epidemiology of Yersiniosis-Foodborne Diseases Active Surveillance Network, 2010-2021.
B20: 2024 Glaucoma as a cause of optic nerve abnormalities on magnetic resonance imaging.
... B32: Enhanced Bayesian Spline Regression Approach for Modelling Trends in Infections Caused by Pathogens Commonly Transmitted Through Food. (Zoonoses (Shannon, Ireland) + 2026)
A35: H002 | B35: Kelly Bijanki · PhD; BA
B36: =HYPERLINK("#Label!G7","← Back to label (row 7)") -> ← Back to label (row 7)
A37: Units | B37: Neurosurgery (SOM)
A38: Email | B38: kbijank@emory.edu
A39: Profile text | B39: (no profile text on the record)
A40: Grant titles | B40: (none on the record)
A41: Titles (10) | B41: 2025 Exploring individual differences in amygdala-mediated memory modulation.
B42: 2021 In Reply: Case Series: Unilateral Amygdala Ablation Ameliorates Post-Traumatic Stress Disorder Symptoms and Biomarkers.
B43: 2020 Case Series: Unilateral Amygdala Ablation Ameliorates Post-Traumatic Stress Disorder Symptoms and Biomarkers.
B44: 2020 Human amygdala stimulation effects on emotion physiology and emotional experience.
B45: 2019 Field potential 1/f activity in the subcallosal cingulate region as a candidate signal for monitoring deep brain stimulation for treatment-resistant depression.
B46: 2019 Cingulum stimulation enhances positive affect and anxiolysis to facilitate awake craniotomy.
B47: 2018 Explaining individual variation in paternal brain responses to infant cries.
B48: 2018 Direct electrical stimulation of the amygdala enhances declarative memory in humans.
B49: 2018 Test-retest reliability of a stimulation-locked evoked response to deep brain stimulation in subcallosal cingulate for treatment resistant depression.
B50: 2015 Depressive symptoms related to low fractional anisotropy of white matter underlying the right ventral anterior cingulate in older adults with atherosclerotic vascular disease.
A53: H003 | B53: Deborah Andresen · MD
B54: =HYPERLINK("#Label!G8","← Back to label (row 8)") -> ← Back to label (row 8)
A55: Units | B55: Pediatrics (SOM)
...

Sheet Progress
A1: Progress
A3: People to label | B3: =ROWS(Label!A6:A155) -> 150
A4: Labelled | B4: =COUNTA(Label!G6:G155) -> 0
A5: Left to do | B5: =B3-B4 -> 150
A6: Done | B6: =IF(B3=0,0,B4/B3) -> 0
A8: W wet | B8: =COUNTIF(Label!G6:G155,"W") -> 0
A9: D dry | B9: =COUNTIF(Label!G6:G155,"D") -> 0
A10: H hybrid | B10: =COUNTIF(Label!G6:G155,"H") -> 0
A11: U can’t tell | B11: =COUNTIF(Label!G6:G155,"U") -> 0
A12: Labelled but Sure? blank | B12: =B4-COUNT(Label!H6:H155) -> 0
A15: Counts update as you fill the Label sheet. The example row is not counted.
